<mujoco model="robot_arm">
  <compiler angle="radian"/>
  <option gravity="0 0 0"/>
  <default>
    <default class="/"/>
    <default class="coordinate_axes/"/>
    <default class="coordinate_axes_1/"/>
    <default class="coordinate_axes_2/"/>
    <default class="coordinate_axes_3/"/>
    <default class="coordinate_axes_4/"/>
    <default class="coordinate_axes_5/"/>
    <default class="coordinate_axes_6/"/>
  </default>
  <asset>
    <texture name="groundplane" type="2d" builtin="checker" rgb1="0.20000000000000001 0.29999999999999999 0.40000000000000002" rgb2="0.5 0.59999999999999998 0.69999999999999996" mark="edge" markrgb="0.80000000000000004 0.80000000000000004 0.80000000000000004" width="300" height="300"/>
    <material name="groundplane" class="/" texture="groundplane" texrepeat="5 5" texuniform="true" reflectance="0.5"/>
    <texture name="metal_gradient_bright" type="2d" builtin="gradient" rgb1="0.80000000000000004 0.80000000000000004 0.80000000000000004" rgb2="0.20000000000000001 0.20000000000000001 0.20000000000000001" width="100" height="100"/>
    <material name="metal_gradient_bright_material" class="/" texture="metal_gradient_bright" texuniform="true" reflectance="0.5"/>
    <texture name="metal_gradient_dark" type="2d" builtin="gradient" rgb1="0.40000000000000002 0.40000000000000002 0.40000000000000002" rgb2="0.80000000000000004 0.80000000000000004 0.80000000000000004" width="100" height="100"/>
    <material name="metal_gradient_dark_material" class="/" texture="metal_gradient_dark" texuniform="true" reflectance="0.5"/>
    <mesh name="base_mesh" class="/" file="magician_lite_base_simple.stl" scale="0.001 0.001 0.001"/>
    <mesh name="link1_mesh" class="/" file="magician_lite_link1_simple.stl" scale="0.001 0.001 0.001"/>
    <mesh name="link2_mesh" class="/" file="magician_lite_link2_simple.stl" scale="0.001 0.001 0.001"/>
    <mesh name="link3_mesh" class="/" file="magician_lite_link3_simple.stl" scale="0.001 0.001 0.001"/>
    <mesh name="link4_mesh" class="/" file="magician_lite_link4_simple.stl" scale="0.001 0.001 0.001"/>
    <mesh name="link5_mesh" class="/" file="magician_lite_link5_simple.stl" scale="0.001 0.001 0.001"/>
    <material name="coordinate_axes/red" class="coordinate_axes/" rgba="1 0 0 1"/>
    <material name="coordinate_axes/green" class="coordinate_axes/" rgba="0 1 0 1"/>
    <material name="coordinate_axes/blue" class="coordinate_axes/" rgba="0 0 1 1"/>
    <material name="coordinate_axes_1/red" class="coordinate_axes_1/" rgba="1 0 0 1"/>
    <material name="coordinate_axes_1/green" class="coordinate_axes_1/" rgba="0 1 0 1"/>
    <material name="coordinate_axes_1/blue" class="coordinate_axes_1/" rgba="0 0 1 1"/>
    <material name="coordinate_axes_2/red" class="coordinate_axes_2/" rgba="1 0 0 1"/>
    <material name="coordinate_axes_2/green" class="coordinate_axes_2/" rgba="0 1 0 1"/>
    <material name="coordinate_axes_2/blue" class="coordinate_axes_2/" rgba="0 0 1 1"/>
    <material name="coordinate_axes_3/red" class="coordinate_axes_3/" rgba="1 0 0 1"/>
    <material name="coordinate_axes_3/green" class="coordinate_axes_3/" rgba="0 1 0 1"/>
    <material name="coordinate_axes_3/blue" class="coordinate_axes_3/" rgba="0 0 1 1"/>
    <material name="coordinate_axes_4/red" class="coordinate_axes_4/" rgba="1 0 0 1"/>
    <material name="coordinate_axes_4/green" class="coordinate_axes_4/" rgba="0 1 0 1"/>
    <material name="coordinate_axes_4/blue" class="coordinate_axes_4/" rgba="0 0 1 1"/>
    <material name="coordinate_axes_5/red" class="coordinate_axes_5/" rgba="1 0 0 1"/>
    <material name="coordinate_axes_5/green" class="coordinate_axes_5/" rgba="0 1 0 1"/>
    <material name="coordinate_axes_5/blue" class="coordinate_axes_5/" rgba="0 0 1 1"/>
    <material name="coordinate_axes_6/red" class="coordinate_axes_6/" rgba="1 0 0 1"/>
    <material name="coordinate_axes_6/green" class="coordinate_axes_6/" rgba="0 1 0 1"/>
    <material name="coordinate_axes_6/blue" class="coordinate_axes_6/" rgba="0 0 1 1"/>
  </asset>
  <worldbody>
    <geom name="ground" class="/" type="plane" size="5 5 1" material="groundplane"/>
    <light name="//unnamed_light_0" class="/" pos="0 0 10" dir="0 0 -1"/>
    <body name="base">
      <geom name="base_geom" class="/" type="mesh" material="metal_gradient_bright_material" pos="0.02 0 0.107" mesh="base_mesh"/>
      <site name="//unnamed_site_0" class="/" pos="0 0 0"/>
      <body pos="0 0 0" name="coordinate_axes/">
        <body name="coordinate_axes/axes">
          <geom name="coordinate_axes//unnamed_geom_0" class="coordinate_axes/" type="capsule" contype="0" conaffinity="0" size="0.0050000000000000001" material="coordinate_axes/red" fromto="0 0 0 0.10000000000000001 0 0"/>
          <geom name="coordinate_axes//unnamed_geom_1" class="coordinate_axes/" type="capsule" contype="0" conaffinity="0" size="0.0050000000000000001" material="coordinate_axes/green" fromto="0 0 0 0 0.10000000000000001 0"/>
          <geom name="coordinate_axes//unnamed_geom_2" class="coordinate_axes/" type="capsule" contype="0" conaffinity="0" size="0.0050000000000000001" material="coordinate_axes/blue" fromto="0 0 0 0 0 0.10000000000000001"/>
        </body>
      </body>
      <body name="link1" pos="0 0 0.12200999999999999" quat="1 0 0 0">
        <geom name="link1_geom" class="/" type="mesh" material="metal_gradient_dark_material" pos="0.02 0 -0.014999999999999999" mesh="link1_mesh"/>
        <site name="//unnamed_site_1" class="/" pos="0 0 0"/>
        <body pos="0 0 0" name="coordinate_axes_1/">
          <body name="coordinate_axes_1/axes">
            <geom name="coordinate_axes_1//unnamed_geom_0" class="coordinate_axes_1/" type="capsule" contype="0" conaffinity="0" size="0.0050000000000000001" material="coordinate_axes_1/red" fromto="0 0 0 0.10000000000000001 0 0"/>
            <geom name="coordinate_axes_1//unnamed_geom_1" class="coordinate_axes_1/" type="capsule" contype="0" conaffinity="0" size="0.0050000000000000001" material="coordinate_axes_1/green" fromto="0 0 0 0 0.10000000000000001 0"/>
            <geom name="coordinate_axes_1//unnamed_geom_2" class="coordinate_axes_1/" type="capsule" contype="0" conaffinity="0" size="0.0050000000000000001" material="coordinate_axes_1/blue" fromto="0 0 0 0 0 0.10000000000000001"/>
          </body>
        </body>
        <joint name="joint1" class="/" type="hinge" axis="0 0 1" range="-3.1415926535897931 3.1415926535897931" damping="0.20000000000000001"/>
        <body name="link2" pos="0 0 0" quat="1 0 0 0">
          <geom name="link2_geom" class="/" type="mesh" material="metal_gradient_bright_material" pos="0.02 0 -0.014999999999999999" mesh="link2_mesh"/>
          <site name="//unnamed_site_2" class="/" pos="0 0 0"/>
          <body pos="0 0 0" name="coordinate_axes_2/">
            <body name="coordinate_axes_2/axes">
              <geom name="coordinate_axes_2//unnamed_geom_0" class="coordinate_axes_2/" type="capsule" contype="0" conaffinity="0" size="0.0050000000000000001" material="coordinate_axes_2/red" fromto="0 0 0 0.10000000000000001 0 0"/>
              <geom name="coordinate_axes_2//unnamed_geom_1" class="coordinate_axes_2/" type="capsule" contype="0" conaffinity="0" size="0.0050000000000000001" material="coordinate_axes_2/green" fromto="0 0 0 0 0.10000000000000001 0"/>
              <geom name="coordinate_axes_2//unnamed_geom_2" class="coordinate_axes_2/" type="capsule" contype="0" conaffinity="0" size="0.0050000000000000001" material="coordinate_axes_2/blue" fromto="0 0 0 0 0 0.10000000000000001"/>
            </body>
          </body>
          <joint name="joint2" class="/" type="hinge" axis="1 0 0" range="-3.1415926535897931 3.1415926535897931" damping="0.20000000000000001"/>
          <body name="link3" pos="0 -0.02 0.14999999999999999" quat="1 0 0 0">
            <geom name="link3_geom" class="/" type="mesh" material="metal_gradient_dark_material" pos="0.02 0.02 -0.16499999999999998" mesh="link3_mesh"/>
            <site name="//unnamed_site_3" class="/" pos="0 0 0"/>
            <body pos="0 0 0" name="coordinate_axes_3/">
              <body name="coordinate_axes_3/axes">
                <geom name="coordinate_axes_3//unnamed_geom_0" class="coordinate_axes_3/" type="capsule" contype="0" conaffinity="0" size="0.0050000000000000001" material="coordinate_axes_3/red" fromto="0 0 0 0.10000000000000001 0 0"/>
                <geom name="coordinate_axes_3//unnamed_geom_1" class="coordinate_axes_3/" type="capsule" contype="0" conaffinity="0" size="0.0050000000000000001" material="coordinate_axes_3/green" fromto="0 0 0 0 0.10000000000000001 0"/>
                <geom name="coordinate_axes_3//unnamed_geom_2" class="coordinate_axes_3/" type="capsule" contype="0" conaffinity="0" size="0.0050000000000000001" material="coordinate_axes_3/blue" fromto="0 0 0 0 0 0.10000000000000001"/>
              </body>
            </body>
            <joint name="joint3" class="/" type="hinge" axis="1 0 0" range="-3.1415926535897931 3.1415926535897931" damping="0.20000000000000001"/>
            <body name="link4" pos="0 -0.16500000000000001 0" quat="1 0 0 0">
              <geom name="link4_geom" class="/" type="mesh" material="metal_gradient_bright_material" pos="0.02 0.185 -0.16499999999999998" mesh="link4_mesh"/>
              <site name="//unnamed_site_4" class="/" pos="0 0 0"/>
              <body pos="0 0 0" name="coordinate_axes_4/">
                <body name="coordinate_axes_4/axes">
                  <geom name="coordinate_axes_4//unnamed_geom_0" class="coordinate_axes_4/" type="capsule" contype="0" conaffinity="0" size="0.0050000000000000001" material="coordinate_axes_4/red" fromto="0 0 0 0.10000000000000001 0 0"/>
                  <geom name="coordinate_axes_4//unnamed_geom_1" class="coordinate_axes_4/" type="capsule" contype="0" conaffinity="0" size="0.0050000000000000001" material="coordinate_axes_4/green" fromto="0 0 0 0 0.10000000000000001 0"/>
                  <geom name="coordinate_axes_4//unnamed_geom_2" class="coordinate_axes_4/" type="capsule" contype="0" conaffinity="0" size="0.0050000000000000001" material="coordinate_axes_4/blue" fromto="0 0 0 0 0 0.10000000000000001"/>
                </body>
              </body>
              <joint name="joint4" class="/" type="hinge" axis="1 0 0" range="-3.1415926535897931 3.1415926535897931" damping="0.20000000000000001"/>
              <body name="link5" pos="0 -0.055 0" quat="1 0 0 0">
                <geom name="link5_geom" class="/" type="mesh" material="metal_gradient_dark_material" pos="0.02 0.23999999999999999 -0.16499999999999998" mesh="link5_mesh"/>
                <site name="//unnamed_site_5" class="/" pos="0 0 0"/>
                <body pos="0 0 0" name="coordinate_axes_5/">
                  <body name="coordinate_axes_5/axes">
                    <geom name="coordinate_axes_5//unnamed_geom_0" class="coordinate_axes_5/" type="capsule" contype="0" conaffinity="0" size="0.0050000000000000001" material="coordinate_axes_5/red" fromto="0 0 0 0.10000000000000001 0 0"/>
                    <geom name="coordinate_axes_5//unnamed_geom_1" class="coordinate_axes_5/" type="capsule" contype="0" conaffinity="0" size="0.0050000000000000001" material="coordinate_axes_5/green" fromto="0 0 0 0 0.10000000000000001 0"/>
                    <geom name="coordinate_axes_5//unnamed_geom_2" class="coordinate_axes_5/" type="capsule" contype="0" conaffinity="0" size="0.0050000000000000001" material="coordinate_axes_5/blue" fromto="0 0 0 0 0 0.10000000000000001"/>
                  </body>
                </body>
                <joint name="joint5" class="/" type="hinge" axis="0 0 1" range="-3.1415926535897931 3.1415926535897931" damping="0.20000000000000001"/>
              </body>
            </body>
          </body>
        </body>
      </body>
    </body>
    <body name="ball">
      <geom name="//unnamed_geom_7" class="/" type="sphere" contype="0" conaffinity="0" size="0.01" rgba="1 1 0 1" pos="0 0 0"/>
      <joint name="joint_x" class="/" type="slide" axis="1 0 0" damping="5"/>
      <joint name="joint_y" class="/" type="slide" axis="0 1 0" damping="5"/>
      <joint name="joint_z" class="/" type="slide" axis="0 0 1" damping="5"/>
      <site name="//unnamed_site_6" class="/"/>
      <body name="coordinate_axes_6/">
        <body name="coordinate_axes_6/axes">
          <geom name="coordinate_axes_6//unnamed_geom_0" class="coordinate_axes_6/" type="capsule" contype="0" conaffinity="0" size="0.0030000000000000001" material="coordinate_axes_6/red" fromto="0 0 0 0.050000000000000003 0 0"/>
          <geom name="coordinate_axes_6//unnamed_geom_1" class="coordinate_axes_6/" type="capsule" contype="0" conaffinity="0" size="0.0030000000000000001" material="coordinate_axes_6/green" fromto="0 0 0 0 0.050000000000000003 0"/>
          <geom name="coordinate_axes_6//unnamed_geom_2" class="coordinate_axes_6/" type="capsule" contype="0" conaffinity="0" size="0.0030000000000000001" material="coordinate_axes_6/blue" fromto="0 0 0 0 0 0.050000000000000003"/>
        </body>
      </body>
    </body>
  </worldbody>
  <actuator>
    <position name="motor1" class="/" ctrlrange="-3.1415926535897931 3.1415926535897931" gear="1" joint="joint1"/>
    <position name="motor2" class="/" ctrlrange="-3.1415926535897931 3.1415926535897931" gear="1" joint="joint2"/>
    <position name="motor3" class="/" ctrlrange="-3.1415926535897931 3.1415926535897931" gear="1" joint="joint3"/>
    <position name="motor4" class="/" ctrlrange="-3.1415926535897931 3.1415926535897931" gear="1" joint="joint4"/>
    <position name="motor5" class="/" ctrlrange="-3.1415926535897931 3.1415926535897931" gear="1" joint="joint5"/>
    <position name="ball_x" class="/" joint="joint_x" kp="20" kv="0.5"/>
    <position name="ball_y" class="/" joint="joint_y" kp="20" kv="0.5"/>
    <position name="ball_z" class="/" joint="joint_z" kp="20" kv="0.5"/>
  </actuator>
</mujoco>
